File: Data/XRD/WC9/WC9_1292b_clay.xrdml
<?xml version="1.0" encoding="UTF-8"?>
<xrdMeasurements xmlns="http://www.xrdml.com/XRDMeasurement/1.5" xmlns:xsi="http://www.w3.org/2001/XMLSchema-instance" xsi:schemaLocation="http://www.xrdml.com/XRDMeasurement/1.5 http://www.xrdml.com/XRDMeasurement/1.5/XRDMeasurement.xsd" status="Completed">
	<comment>
		<entry>Configuration=Reflection-transmission Spinner, Owner=User-1, Creation date=6/1/2015 7:12:58 PM</entry>
		<entry>Goniometer=Theta/Theta; Minimum step size 2Theta:0.0001; Minimum step size Omega:0.0001</entry>
		<entry>Sample stage=Reflection-transmission spinner; Minimum step size Phi:0.1</entry>
		<entry>Diffractometer system=EMPYREAN</entry>
		<entry>Measurement program=C:\XRD Data\Programs\Nick_absolute_scan_060.xrdmp, Identifier={8F03A150-B3AE-4918-A1AD-4626C436851B}</entry>
		<entry>Batch program=C:\XRD Data\Programs\Tosca Group\Nick\Nick_batch_scan_2.xrdmp, Identifier={8E3C1DBC-55CE-4A0B-8B97-6D647A05FBA0}</entry>
	</comment>
	<sample type="To be analyzed">
		<id></id>
		<name></name>
		<preparedBy></preparedBy>
	</sample>
	<xrdMeasurement measurementType="Scan" status="Completed" sampleMode="Reflection">
		<comment>
			<entry>Ref Trans spinner</entry>
		</comment>
		<usedWavelength intended="K-Alpha 1">
			<kAlpha1 unit="Angstrom">1.7890100</kAlpha1>
			<kAlpha2 unit="Angstrom">1.7929000</kAlpha2>
			<kBeta unit="Angstrom">1.6208300</kBeta>
			<ratioKAlpha2KAlpha1>0.5000</ratioKAlpha2KAlpha1>
		</usedWavelength>
		<incidentBeamPath>
			<radius unit="mm">240.00</radius>
			<xRayTube id="1010042" name="Empyrean Co LFF (9430 033 7600x) DK406408">
				<tension unit="kV">40</tension>
				<current unit="mA">40</current>
				<anodeMaterial>Co</anodeMaterial>
				<focus type="Line">
					<length unit="mm">12.0</length>
					<width unit="mm">0.4</width>
					<takeOffAngle unit="deg">6.0</takeOffAngle>
				</focus>
			</xRayTube>
			<sollerSlit id="21010002" name="Soller slits 0.04 rad.">
				<opening unit="rad">0.0400</opening>
			</sollerSlit>
			<mask id="22080004" name="Fixed incident beam mask 20 mm">
				<width unit="mm">17.20</width>
			</mask>
			<antiScatterSlit id="22010002" name="Fixed slit 2Â°" xsi:type="fixedAntiScatterSlitType">
				<height unit="mm">3.03</height>
			</antiScatterSlit>
			<divergenceSlit id="22010012" name="Programmable divergence slit" xsi:type="fixedDivergenceSlitType">
				<distanceToSample unit="mm">140.00</distanceToSample>
				<angle unit="deg">2</angle>
			</divergenceSlit>
		</incidentBeamPath>
		<sampleMovement xsi:type="spinningSampleMovementType">
			<spinnerRevolutionTime unit="seconds">2.0</spinnerRevolutionTime>
		</sampleMovement>
		<diffractedBeamPath>
			<radius unit="mm">240.00</radius>
			<antiScatterSlit id="22060009" name="Programmable anti-scatter slit" xsi:type="fixedAntiScatterSlitType">
				<angle unit="deg">2</angle>
			</antiScatterSlit>
			<sollerSlit id="21020003" name="Large Soller slits 0.04 rad.">
				<opening unit="rad">0.0400</opening>
			</sollerSlit>
			<filter id="20030002" name="Large beta-filter Iron">
				<material>Fe</material>
				<thickness unit="mm">0.016</thickness>
			</filter>
			<detector id="7010019" name="PIXcel1D-Medipix3 detector" xsi:type="rtmsDetectorType">
				<phd>
					<lowerLevel unit="%">27.5</lowerLevel>
					<upperLevel unit="%">70.0</upperLevel>
				</phd>
				<mode>Scanning</mode>
				<activeLength unit="deg">3.3473</activeLength>
			</detector>
		</diffractedBeamPath>
		<scan appendNumber="0" mode="Continuous" scanAxis="Gonio" status="Completed">
			<header>
				<startTimeStamp>2019-11-14T14:27:28+00:00</startTimeStamp>
				<endTimeStamp>2019-11-14T14:34:34+00:00</endTimeStamp>
				<author>
					<name>User</name>
				</author>
				<source>
					<applicationSoftware version="5.1a">Data Collector</applicationSoftware>
					<instrumentControlSoftware version="7.9j 20171025">EMPYREAN</instrumentControlSoftware>
					<instrumentID>0000000011167697</instrumentID>
				</source>
			</header>
			<dataPoints>
				<positions axis="2Theta" unit="deg">
					<startPosition>69.02573028</startPosition>
					<endPosition>74.98687854</endPosition>
				</positions>
				<positions axis="Omega" unit="deg">
					<startPosition>34.51286514</startPosition>
					<endPosition>37.49343927</endPosition>
				</positions>
				<positions axis="Phi" unit="deg">
					<commonPosition>351.7</commonPosition>
				</positions>
				<commonCountingTime unit="seconds">297.840</commonCountingTime>
				<intensities unit="counts">19332 19204 19367 19304 19192 19317 19415 19390 19677 19461 19585 19529 19432 19510 19648 19403 19582 19745 19693 19634 19390 19662 19696 19483 19727 19599 19627 19687 19634 19603 19386 19629 19868 19845 19663 19757 19771 20247 19914 20032 20039 20090 20574 20428 20502 20527 20945 20533 21036 20749 20892 21058 21372 21578 21690 21669 21639 22074 22352 22052 22079 22219 22291 22238 22431 22951 23262 24374 25941 28366 30741 31473 29815 27559 26101 25742 25936 26403 25721 24541 23051 22008 21747 20837 20920 20527 20283 20384 20245 20211 19909 20168 20172 20179 20155 19885 19638 19715 20014 19707 19906 19763 19848 20128 20163 20067 19847 20003 19844 19726 19894 20055 19785 19797 20040 19889 19931 19690 20126 19737 19908 20067 20144 20107 20409 20534 20551 20448 20497 20416 20862 21009 20993 21184 21024 21175 21403 21272 21529 21474 21629 21819 21866 22313 22006 21956 21978 22184 22421 22375 22318 22470 22102 22536 22179 21876 22043 22009 21832 21690 21376 21253 21188 21117 20662 20985 20717 20514 20287 20130 20083 19867 19984 19702 19931 19729 19556 19484 19684 19714 19420 19299 19477 19557 19506 19448 19578 19492 19642 19592 19133 19200 19121 19410 19005 19244 19222 18835 18861 18985 19061 18425 18529 18488 18850 18892 18662 18446 18529 18485 18463 18367 18748 18392 18335 18497 18491 18393 18612 18431 18314 18505 18492 18425 18341 18459 18131 18407</intensities>
			</dataPoints>
		</scan>
	</xrdMeasurement>
</xrdMeasurements>