File: Data/XRD/WC9/WC9_1400b_clay.xrdml
<?xml version="1.0" encoding="UTF-8"?>
<xrdMeasurements xmlns="http://www.xrdml.com/XRDMeasurement/1.5" xmlns:xsi="http://www.w3.org/2001/XMLSchema-instance" xsi:schemaLocation="http://www.xrdml.com/XRDMeasurement/1.5 http://www.xrdml.com/XRDMeasurement/1.5/XRDMeasurement.xsd" status="Completed">
	<comment>
		<entry>Configuration=Reflection-transmission Spinner, Owner=User-1, Creation date=6/1/2015 7:12:58 PM</entry>
		<entry>Goniometer=Theta/Theta; Minimum step size 2Theta:0.0001; Minimum step size Omega:0.0001</entry>
		<entry>Sample stage=Reflection-transmission spinner; Minimum step size Phi:0.1</entry>
		<entry>Diffractometer system=EMPYREAN</entry>
		<entry>Measurement program=C:\XRD Data\Programs\Nick_absolute_scan_060.xrdmp, Identifier={8F03A150-B3AE-4918-A1AD-4626C436851B}</entry>
		<entry>Batch program=C:\XRD Data\Programs\Tosca Group\Nick\Nick_batch_scan_2.xrdmp, Identifier={F0B5BA54-BEAE-474D-A0E3-B46BD7E7024E}</entry>
	</comment>
	<sample type="To be analyzed">
		<id></id>
		<name></name>
		<preparedBy></preparedBy>
	</sample>
	<xrdMeasurement measurementType="Scan" status="Completed" sampleMode="Reflection">
		<comment>
			<entry>Ref Trans spinner</entry>
		</comment>
		<usedWavelength intended="K-Alpha 1">
			<kAlpha1 unit="Angstrom">1.7890100</kAlpha1>
			<kAlpha2 unit="Angstrom">1.7929000</kAlpha2>
			<kBeta unit="Angstrom">1.6208300</kBeta>
			<ratioKAlpha2KAlpha1>0.5000</ratioKAlpha2KAlpha1>
		</usedWavelength>
		<incidentBeamPath>
			<radius unit="mm">240.00</radius>
			<xRayTube id="1010042" name="Empyrean Co LFF (9430 033 7600x) DK406408">
				<tension unit="kV">40</tension>
				<current unit="mA">40</current>
				<anodeMaterial>Co</anodeMaterial>
				<focus type="Line">
					<length unit="mm">12.0</length>
					<width unit="mm">0.4</width>
					<takeOffAngle unit="deg">6.0</takeOffAngle>
				</focus>
			</xRayTube>
			<sollerSlit id="21010002" name="Soller slits 0.04 rad.">
				<opening unit="rad">0.0400</opening>
			</sollerSlit>
			<mask id="22080004" name="Fixed incident beam mask 20 mm">
				<width unit="mm">17.20</width>
			</mask>
			<antiScatterSlit id="22010002" name="Fixed slit 2Â°" xsi:type="fixedAntiScatterSlitType">
				<height unit="mm">3.03</height>
			</antiScatterSlit>
			<divergenceSlit id="22010012" name="Programmable divergence slit" xsi:type="fixedDivergenceSlitType">
				<distanceToSample unit="mm">140.00</distanceToSample>
				<angle unit="deg">2</angle>
			</divergenceSlit>
		</incidentBeamPath>
		<sampleMovement xsi:type="spinningSampleMovementType">
			<spinnerRevolutionTime unit="seconds">2.0</spinnerRevolutionTime>
		</sampleMovement>
		<diffractedBeamPath>
			<radius unit="mm">240.00</radius>
			<antiScatterSlit id="22060009" name="Programmable anti-scatter slit" xsi:type="fixedAntiScatterSlitType">
				<angle unit="deg">2</angle>
			</antiScatterSlit>
			<sollerSlit id="21020003" name="Large Soller slits 0.04 rad.">
				<opening unit="rad">0.0400</opening>
			</sollerSlit>
			<filter id="20030002" name="Large beta-filter Iron">
				<material>Fe</material>
				<thickness unit="mm">0.016</thickness>
			</filter>
			<detector id="7010019" name="PIXcel1D-Medipix3 detector" xsi:type="rtmsDetectorType">
				<phd>
					<lowerLevel unit="%">27.5</lowerLevel>
					<upperLevel unit="%">70.0</upperLevel>
				</phd>
				<mode>Scanning</mode>
				<activeLength unit="deg">3.3473</activeLength>
			</detector>
		</diffractedBeamPath>
		<scan appendNumber="0" mode="Continuous" scanAxis="Gonio" status="Completed">
			<header>
				<startTimeStamp>2019-11-19T10:19:50+00:00</startTimeStamp>
				<endTimeStamp>2019-11-19T10:26:58+00:00</endTimeStamp>
				<author>
					<name>User</name>
				</author>
				<source>
					<applicationSoftware version="5.1a">Data Collector</applicationSoftware>
					<instrumentControlSoftware version="7.9j 20171025">EMPYREAN</instrumentControlSoftware>
					<instrumentID>0000000011167697</instrumentID>
				</source>
			</header>
			<dataPoints>
				<positions axis="2Theta" unit="deg">
					<startPosition>69.02573028</startPosition>
					<endPosition>74.98687854</endPosition>
				</positions>
				<positions axis="Omega" unit="deg">
					<startPosition>34.51286514</startPosition>
					<endPosition>37.49343927</endPosition>
				</positions>
				<positions axis="Phi" unit="deg">
					<commonPosition>273.9</commonPosition>
				</positions>
				<commonCountingTime unit="seconds">297.840</commonCountingTime>
				<intensities unit="counts">18006 17656 17897 18282 18223 18140 17986 18187 17939 18310 18208 18485 18669 18624 18554 18492 18012 18352 18626 18114 18447 18326 18140 18322 18333 18210 18448 18460 18452 18420 18305 18297 18486 18434 18591 18599 18631 18833 18454 18755 18661 18674 18817 18884 18628 18797 18651 19017 18938 19063 19094 19428 19495 19624 19487 19753 19929 20167 19907 20045 20538 20215 20321 20341 20458 20727 21249 22438 23397 25820 29667 32715 32515 29955 27014 25031 24908 26191 26359 25730 23707 21960 20553 19899 19684 19318 19196 18708 18796 18685 18971 18580 18608 18434 18510 18546 18616 18255 18406 18484 18413 18446 18355 18650 18590 18417 18201 18426 18459 18522 18516 18489 18610 18416 18440 18566 18664 18355 18644 18693 18630 18630 18663 18685 18767 18517 18783 18864 19045 19271 19159 19190 19253 19072 19384 19763 19552 19353 19706 20035 20164 20082 20337 20473 20325 20651 20710 20747 21056 20806 21177 20941 21012 20793 20752 20846 20705 20611 20465 20320 20231 20144 19643 19541 19622 19321 19466 19049 19027 18804 18713 18565 18489 18618 18393 18236 18295 18397 18186 18115 18362 18328 18142 18057 18172 18011 18137 18178 17914 18092 18143 17940 17973 17801 17956 17816 17762 17766 17794 17570 17296 17354 17359 17339 17443 17530 17060 17634 17297 17351 17246 17082 17114 17236 17041 17213 17160 17016 16981 17290 17222 17148 17251 17252 17352 17151 17006 17100</intensities>
			</dataPoints>
		</scan>
	</xrdMeasurement>
</xrdMeasurements>