File: Data/XRD/WC9/WC9_1439b_clay.xrdml
<?xml version="1.0" encoding="UTF-8"?>
<xrdMeasurements xmlns="http://www.xrdml.com/XRDMeasurement/1.5" xmlns:xsi="http://www.w3.org/2001/XMLSchema-instance" xsi:schemaLocation="http://www.xrdml.com/XRDMeasurement/1.5 http://www.xrdml.com/XRDMeasurement/1.5/XRDMeasurement.xsd" status="Completed">
	<comment>
		<entry>Configuration=Reflection-transmission Spinner, Owner=User-1, Creation date=6/1/2015 7:12:58 PM</entry>
		<entry>Goniometer=Theta/Theta; Minimum step size 2Theta:0.0001; Minimum step size Omega:0.0001</entry>
		<entry>Sample stage=Reflection-transmission spinner; Minimum step size Phi:0.1</entry>
		<entry>Diffractometer system=EMPYREAN</entry>
		<entry>Measurement program=C:\XRD Data\Programs\Nick_absolute_scan_060.xrdmp, Identifier={8F03A150-B3AE-4918-A1AD-4626C436851B}</entry>
		<entry>Batch program=C:\XRD Data\Programs\Tosca Group\Nick\Nick_batch_scan_2.xrdmp, Identifier={F0B5BA54-BEAE-474D-A0E3-B46BD7E7024E}</entry>
	</comment>
	<sample type="To be analyzed">
		<id></id>
		<name></name>
		<preparedBy></preparedBy>
	</sample>
	<xrdMeasurement measurementType="Scan" status="Completed" sampleMode="Reflection">
		<comment>
			<entry>Ref Trans spinner</entry>
		</comment>
		<usedWavelength intended="K-Alpha 1">
			<kAlpha1 unit="Angstrom">1.7890100</kAlpha1>
			<kAlpha2 unit="Angstrom">1.7929000</kAlpha2>
			<kBeta unit="Angstrom">1.6208300</kBeta>
			<ratioKAlpha2KAlpha1>0.5000</ratioKAlpha2KAlpha1>
		</usedWavelength>
		<incidentBeamPath>
			<radius unit="mm">240.00</radius>
			<xRayTube id="1010042" name="Empyrean Co LFF (9430 033 7600x) DK406408">
				<tension unit="kV">40</tension>
				<current unit="mA">40</current>
				<anodeMaterial>Co</anodeMaterial>
				<focus type="Line">
					<length unit="mm">12.0</length>
					<width unit="mm">0.4</width>
					<takeOffAngle unit="deg">6.0</takeOffAngle>
				</focus>
			</xRayTube>
			<sollerSlit id="21010002" name="Soller slits 0.04 rad.">
				<opening unit="rad">0.0400</opening>
			</sollerSlit>
			<mask id="22080004" name="Fixed incident beam mask 20 mm">
				<width unit="mm">17.20</width>
			</mask>
			<antiScatterSlit id="22010002" name="Fixed slit 2Â°" xsi:type="fixedAntiScatterSlitType">
				<height unit="mm">3.03</height>
			</antiScatterSlit>
			<divergenceSlit id="22010012" name="Programmable divergence slit" xsi:type="fixedDivergenceSlitType">
				<distanceToSample unit="mm">140.00</distanceToSample>
				<angle unit="deg">2</angle>
			</divergenceSlit>
		</incidentBeamPath>
		<sampleMovement xsi:type="spinningSampleMovementType">
			<spinnerRevolutionTime unit="seconds">2.0</spinnerRevolutionTime>
		</sampleMovement>
		<diffractedBeamPath>
			<radius unit="mm">240.00</radius>
			<antiScatterSlit id="22060009" name="Programmable anti-scatter slit" xsi:type="fixedAntiScatterSlitType">
				<angle unit="deg">2</angle>
			</antiScatterSlit>
			<sollerSlit id="21020003" name="Large Soller slits 0.04 rad.">
				<opening unit="rad">0.0400</opening>
			</sollerSlit>
			<filter id="20030002" name="Large beta-filter Iron">
				<material>Fe</material>
				<thickness unit="mm">0.016</thickness>
			</filter>
			<detector id="7010019" name="PIXcel1D-Medipix3 detector" xsi:type="rtmsDetectorType">
				<phd>
					<lowerLevel unit="%">27.5</lowerLevel>
					<upperLevel unit="%">70.0</upperLevel>
				</phd>
				<mode>Scanning</mode>
				<activeLength unit="deg">3.3473</activeLength>
			</detector>
		</diffractedBeamPath>
		<scan appendNumber="0" mode="Continuous" scanAxis="Gonio" status="Completed">
			<header>
				<startTimeStamp>2019-11-19T10:27:42+00:00</startTimeStamp>
				<endTimeStamp>2019-11-19T10:34:49+00:00</endTimeStamp>
				<author>
					<name>User</name>
				</author>
				<source>
					<applicationSoftware version="5.1a">Data Collector</applicationSoftware>
					<instrumentControlSoftware version="7.9j 20171025">EMPYREAN</instrumentControlSoftware>
					<instrumentID>0000000011167697</instrumentID>
				</source>
			</header>
			<dataPoints>
				<positions axis="2Theta" unit="deg">
					<startPosition>69.02573028</startPosition>
					<endPosition>74.98687854</endPosition>
				</positions>
				<positions axis="Omega" unit="deg">
					<startPosition>34.51286514</startPosition>
					<endPosition>37.49343927</endPosition>
				</positions>
				<positions axis="Phi" unit="deg">
					<commonPosition>322.4</commonPosition>
				</positions>
				<commonCountingTime unit="seconds">297.840</commonCountingTime>
				<intensities unit="counts">15024 14999 15056 15037 14958 15088 15110 15197 15406 15277 15474 15592 15346 15031 15193 15403 15254 15367 15441 15325 15402 15528 15424 15323 15279 15425 15698 15406 15161 15260 15435 15507 15375 15267 15441 15772 15930 15499 15638 15686 15668 15814 15807 15970 15844 15839 16019 16041 16029 16375 16273 16403 16279 16658 16397 16935 17011 16778 16439 17154 17136 16962 16853 16803 17232 17420 18058 18971 20731 23150 25065 24203 21552 19655 19320 19210 20288 20803 19349 18125 17077 16540 16310 15949 15847 15244 15670 15628 15493 15513 15547 15131 15329 15224 15429 15256 15445 15321 15333 15146 15184 15365 15590 15260 15462 15490 15357 15499 15708 15401 15374 15440 15296 15668 15362 15508 15406 15418 15427 15631 15469 15709 15741 15806 15831 16230 15858 16172 15990 16110 16032 16073 16467 16415 16472 16429 16658 16826 17032 16856 17253 17392 17386 17700 17655 17823 17748 18029 18340 18005 18443 18004 18301 18197 18087 17763 17921 17765 17556 17267 17231 16939 16931 16859 16694 16121 16328 16178 15948 15784 15560 15443 15598 15473 15422 15435 15334 15187 15145 15129 15030 14986 14794 14867 14661 14715 14987 14782 14842 14771 14535 14716 14747 14467 14726 14465 14527 14688 14554 14655 14604 14570 14408 14282 14233 14636 14301 14475 14359 14082 14110 14073 14205 14185 14153 14110 14215 14270 14204 14166 14183 14014 14197 14093 14051 14015 13770 13986</intensities>
			</dataPoints>
		</scan>
	</xrdMeasurement>
</xrdMeasurements>