File: Data/XRD/D08/D08_1100b_clay.xrdml
<?xml version="1.0" encoding="UTF-8"?>
<xrdMeasurements xmlns="http://www.xrdml.com/XRDMeasurement/1.5" xmlns:xsi="http://www.w3.org/2001/XMLSchema-instance" xsi:schemaLocation="http://www.xrdml.com/XRDMeasurement/1.5 http://www.xrdml.com/XRDMeasurement/1.5/XRDMeasurement.xsd" status="Completed">
	<comment>
		<entry>Configuration=Reflection-transmission Spinner, Owner=User-1, Creation date=6/1/2015 7:12:58 PM</entry>
		<entry>Goniometer=Theta/Theta; Minimum step size 2Theta:0.0001; Minimum step size Omega:0.0001</entry>
		<entry>Sample stage=Reflection-transmission spinner; Minimum step size Phi:0.1</entry>
		<entry>Diffractometer system=EMPYREAN</entry>
		<entry>Measurement program=C:\XRD Data\Programs\Nick_absolute_scan_060.xrdmp, Identifier={8F03A150-B3AE-4918-A1AD-4626C436851B}</entry>
		<entry>Batch program=C:\XRD Data\Programs\Tosca Group\Nick\Nick_batch_scan_2.xrdmp, Identifier={8E3C1DBC-55CE-4A0B-8B97-6D647A05FBA0}</entry>
	</comment>
	<sample type="To be analyzed">
		<id></id>
		<name></name>
		<preparedBy></preparedBy>
	</sample>
	<xrdMeasurement measurementType="Scan" status="Completed" sampleMode="Reflection">
		<comment>
			<entry>Ref Trans spinner</entry>
		</comment>
		<usedWavelength intended="K-Alpha 1">
			<kAlpha1 unit="Angstrom">1.7890100</kAlpha1>
			<kAlpha2 unit="Angstrom">1.7929000</kAlpha2>
			<kBeta unit="Angstrom">1.6208300</kBeta>
			<ratioKAlpha2KAlpha1>0.5000</ratioKAlpha2KAlpha1>
		</usedWavelength>
		<incidentBeamPath>
			<radius unit="mm">240.00</radius>
			<xRayTube id="1010042" name="Empyrean Co LFF (9430 033 7600x) DK406408">
				<tension unit="kV">40</tension>
				<current unit="mA">40</current>
				<anodeMaterial>Co</anodeMaterial>
				<focus type="Line">
					<length unit="mm">12.0</length>
					<width unit="mm">0.4</width>
					<takeOffAngle unit="deg">6.0</takeOffAngle>
				</focus>
			</xRayTube>
			<sollerSlit id="21010002" name="Soller slits 0.04 rad.">
				<opening unit="rad">0.0400</opening>
			</sollerSlit>
			<mask id="22080004" name="Fixed incident beam mask 20 mm">
				<width unit="mm">17.20</width>
			</mask>
			<antiScatterSlit id="22010002" name="Fixed slit 2Â°" xsi:type="fixedAntiScatterSlitType">
				<height unit="mm">3.03</height>
			</antiScatterSlit>
			<divergenceSlit id="22010012" name="Programmable divergence slit" xsi:type="fixedDivergenceSlitType">
				<distanceToSample unit="mm">140.00</distanceToSample>
				<angle unit="deg">2</angle>
			</divergenceSlit>
		</incidentBeamPath>
		<sampleMovement xsi:type="spinningSampleMovementType">
			<spinnerRevolutionTime unit="seconds">2.0</spinnerRevolutionTime>
		</sampleMovement>
		<diffractedBeamPath>
			<radius unit="mm">240.00</radius>
			<antiScatterSlit id="22060009" name="Programmable anti-scatter slit" xsi:type="fixedAntiScatterSlitType">
				<angle unit="deg">2</angle>
			</antiScatterSlit>
			<sollerSlit id="21020003" name="Large Soller slits 0.04 rad.">
				<opening unit="rad">0.0400</opening>
			</sollerSlit>
			<filter id="20030002" name="Large beta-filter Iron">
				<material>Fe</material>
				<thickness unit="mm">0.016</thickness>
			</filter>
			<detector id="7010019" name="PIXcel1D-Medipix3 detector" xsi:type="rtmsDetectorType">
				<phd>
					<lowerLevel unit="%">27.5</lowerLevel>
					<upperLevel unit="%">70.0</upperLevel>
				</phd>
				<mode>Scanning</mode>
				<activeLength unit="deg">3.3473</activeLength>
			</detector>
		</diffractedBeamPath>
		<scan appendNumber="0" mode="Continuous" scanAxis="Gonio" status="Completed">
			<header>
				<startTimeStamp>2019-11-14T13:40:24+00:00</startTimeStamp>
				<endTimeStamp>2019-11-14T13:47:31+00:00</endTimeStamp>
				<author>
					<name>User</name>
				</author>
				<source>
					<applicationSoftware version="5.1a">Data Collector</applicationSoftware>
					<instrumentControlSoftware version="7.9j 20171025">EMPYREAN</instrumentControlSoftware>
					<instrumentID>0000000011167697</instrumentID>
				</source>
			</header>
			<dataPoints>
				<positions axis="2Theta" unit="deg">
					<startPosition>69.02573028</startPosition>
					<endPosition>74.98687854</endPosition>
				</positions>
				<positions axis="Omega" unit="deg">
					<startPosition>34.51286514</startPosition>
					<endPosition>37.49343927</endPosition>
				</positions>
				<positions axis="Phi" unit="deg">
					<commonPosition>115.6</commonPosition>
				</positions>
				<commonCountingTime unit="seconds">297.840</commonCountingTime>
				<intensities unit="counts">14410 14447 14727 14259 14520 14626 14591 14675 14992 15066 15130 14936 15247 14996 14757 15150 15181 15070 15183 15011 14946 15043 15116 15059 15140 15386 15536 15726 15435 15323 15240 15293 15218 15330 15338 15547 15145 15143 15166 15169 15344 15222 14978 15217 15318 15388 15121 15091 15187 15437 15307 15343 15776 15608 15694 15722 16049 15805 15797 16005 16022 16095 16292 16432 16552 17182 18024 18742 20619 24033 27332 28481 26175 23037 21423 20903 21371 21994 21843 20222 18103 17106 16095 15894 15713 15640 15403 15335 15156 15047 14864 15004 14885 14905 15031 14958 14826 14800 14777 14800 15006 14843 15004 14898 14969 14802 14698 15000 14848 15143 15029 15029 14917 14932 14820 15000 14977 14841 14969 14800 15003 14972 14943 15064 15148 15424 15257 15269 15267 15362 15506 15434 15497 15557 15743 15821 15982 16074 16096 16378 16298 16630 17107 16956 16975 17168 17490 17571 18145 18500 18895 18994 19549 19853 19212 18933 18347 18484 18380 18565 17854 17738 17531 17093 16911 16358 16235 16075 15883 15711 15510 15625 15246 15185 14924 15204 14745 14813 14633 14561 14402 14614 14893 14338 14335 14268 14383 14212 14251 14356 14240 14194 14282 14089 14277 14088 14459 14419 14251 14163 14193 14129 14031 14399 14156 14047 14054 14043 14110 13746 13958 14054 13887 13818 13714 13812 13663 13728 13598 13720 13649 13849 13630 13819 13742 13876 13938 13815</intensities>
			</dataPoints>
		</scan>
	</xrdMeasurement>
</xrdMeasurements>