File: Data/XRD/Clay Peels/D08_993b_claypeel.csv
[Measurement conditions]
Sample identification,
Comment - 1,"Configuration=Reflection-transmission Spinner, Owner=User-1, Creation date=6/1/2015 7:12:58 PM"
Comment - 2,"Goniometer=Theta/Theta; Minimum step size 2Theta:0.0001; Minimum step size Omega:0.0001"
Comment - 3,"Sample stage=Reflection-transmission spinner; Minimum step size Phi:0.1"
Comment - 4,"Diffractometer system=EMPYREAN"
Comment - 5,"Measurement program=C:\XRD Data\Programs\Tosca Group\Nick\Nick_absolute_scan_CLAYSCAN.xrdmp, Identifier={8AE44CAB-C35C-4B16-AEF4-F65C0B9E5FF8}"
Comment - 6,"Batch program=C:\XRD Data\Programs\Tosca Group\Nick\Nick_batch_scan_2.xrdmp, Identifier={0D27121D-1F70-4E1C-B072-8710C01E5568}"
Anode material,Co
K-Alpha1 wavelength,1.7890100
K-Alpha2 wavelength,1.7929000
Ratio K-Alpha2/K-Alpha1,0.500
Divergence slit,Fixed,0.5
Monochromator used,NO
Generator voltage, 40
Tube current, 40
File date and time,20/Jan/2020 17:02
Unit cell,
h k l, 0 0 0
Scan axis,Gonio
Scan range,5.005199997,45.000040503
Scan step size,0.0262606
No. of points, 1523
Scan type,CONTINUOUS
Phi,223.9
Time per step,197.115
[Scan points]
Angle,Intensity
5.020000000,14814.6
5.060000000,14854.2
5.100000000,14571.1
5.140000000,14772.3
5.180000000,14880.2
5.220000000,14832.1
5.260000000,14928.9
5.300000000,14895.6
5.340000000,14747.8
5.380000000,14872.0
5.420000000,14746.0
5.460000000,14694.4
5.500000000,14760.7
5.540000000,14972.5
5.580000000,14843.5
5.620000000,14996.1
5.660000000,15030.3
5.700000000,14867.7
5.740000000,14991.7
5.780000000,14828.5
5.820000000,15088.9
5.860000000,15087.9
5.900000000,15150.5
5.940000000,15079.0
5.980000000,15041.6
6.020000000,15334.2
6.060000000,15297.3
6.100000000,15294.7
6.140000000,15573.0
6.180000000,15449.1
6.220000000,15557.9
6.260000000,15510.8
6.300000000,15768.8
6.340000000,15645.7
6.380000000,15617.7
6.420000000,15802.3
6.460000000,15877.7
6.500000000,16045.7
6.540000000,16056.4
6.580000000,16145.7
6.620000000,16515.2
6.660000000,16546.5
6.700000000,16728.8
6.740000000,17068.4
6.780000000,17038.1
6.820000000,17467.6
6.860000000,17845.3
6.900000000,18257.5
6.940000000,19029.8
6.980000000,19621.0
7.020000000,20641.2
7.060000000,21307.5
7.100000000,22442.1
7.140000000,22872.4
7.180000000,22926.6
7.220000000,21697.5
7.260000000,20247.5
7.300000000,19755.3
7.340000000,19098.9
7.380000000,18986.5
7.420000000,18594.3
7.460000000,18349.1
7.500000000,18212.5
7.540000000,17825.5
7.580000000,18008.3
7.620000000,18461.5
7.660000000,18058.8
7.700000000,18245.7
7.740000000,18310.5
7.780000000,18477.0
7.820000000,18511.1
7.860000000,18343.9
7.900000000,18507.0
7.940000000,18316.7
7.980000000,18466.2
8.020000000,18753.2
8.060000000,19227.6
8.100000000,19227.2
8.140000000,19512.3
8.180000000,19699.3
8.220000000,19810.5
8.260000000,20023.6
8.300000000,20193.7
8.340000000,20714.8
8.380000000,20842.6
8.420000000,21107.8
8.460000000,21329.1
8.500000000,21648.8
8.540000000,22097.5
8.580000000,22356.1
8.620000000,22843.7
8.660000000,23361.1
8.700000000,23740.5
8.740000000,24181.2
8.780000000,25038.5
8.820000000,25266.7
8.860000000,25940.6
8.900000000,26361.9
8.940000000,27379.1
8.980000000,27751.4
9.020000000,28412.0
9.060000000,29406.8
9.100000000,29713.4
9.140000000,30368.4
9.180000000,31213.7
9.220000000,32098.5
9.260000000,32862.5
9.300000000,33565.9
9.340000000,34459.4
9.380000000,35116.0
9.420000000,35615.3
9.460000000,36405.8
9.500000000,37357.4
9.540000000,37582.6
9.580000000,38266.9
9.620000000,39015.7
9.660000000,39918.1
9.700000000,40571.0
9.740000000,42012.2
9.780000000,42694.6
9.820000000,44668.6
9.860000000,45668.9
9.900000000,47698.2
9.940000000,49609.6
9.980000000,51699.8
10.020000000,55544.4
10.060000000,60006.4
10.100000000,64298.1
10.140000000,70314.3
10.180000000,74148.8
10.220000000,71789.5
10.260000000,59560.0
10.300000000,45660.8
10.340000000,37225.3
10.380000000,31293.0
10.420000000,27632.3
10.460000000,25097.3
10.500000000,23193.7
10.540000000,21498.2
10.580000000,20398.1
10.620000000,19293.8
10.660000000,18575.8
10.700000000,17523.2
10.740000000,17090.1
10.780000000,16389.8
10.820000000,16031.5
10.860000000,15666.4
10.900000000,15552.3
10.940000000,15207.0
10.980000000,14857.2
11.020000000,14661.7
11.060000000,14338.9
11.100000000,14245.0
11.140000000,14076.1
11.180000000,13837.6
11.220000000,13751.9
11.260000000,13523.6
11.300000000,13600.3
11.340000000,13500.3
11.380000000,13385.5
11.420000000,13015.6
11.460000000,13232.2
11.500000000,13268.9
11.540000000,13068.7
11.580000000,13132.0
11.620000000,12898.5
11.660000000,12789.9
11.700000000,12881.9
11.740000000,12637.3
11.780000000,12716.0
11.820000000,12857.1
11.860000000,12815.7
11.900000000,12910.5
11.940000000,12858.6
11.980000000,12989.6
12.020000000,12766.8
12.060000000,12748.8
12.100000000,12538.0
12.140000000,12567.3
12.180000000,12620.1
12.220000000,12602.1
12.260000000,12602.2
12.300000000,12447.3
12.340000000,12530.8
12.380000000,12484.1
12.420000000,12419.1
12.460000000,12656.5
12.500000000,12507.4
12.540000000,12546.9
12.580000000,12495.7
12.620000000,12498.5
12.660000000,12417.3
12.700000000,12595.7
12.740000000,12709.4
12.780000000,12334.3
12.820000000,12430.4
12.860000000,12474.8
12.900000000,12546.1
12.940000000,12561.2
12.980000000,12612.2
13.020000000,12598.0
13.060000000,12602.0
13.100000000,12743.9
13.140000000,12775.2
13.180000000,12668.6
13.220000000,12551.0
13.260000000,12415.4
13.300000000,12700.3
13.340000000,12729.8
13.380000000,12753.9
13.420000000,12693.7
13.460000000,12959.1
13.500000000,12839.1
13.540000000,13182.5
13.580000000,12954.4
13.620000000,13218.8
13.660000000,13397.5
13.700000000,13371.4
13.740000000,13556.1
13.780000000,13711.6
13.820000000,14007.4
13.860000000,14453.9
13.900000000,14879.7
13.940000000,15505.9
13.980000000,16086.8
14.020000000,16691.5
14.060000000,17703.8
14.100000000,18842.9
14.140000000,20595.3
14.180000000,22387.1
14.220000000,24724.4
14.260000000,27670.1
14.300000000,31030.8
14.340000000,35020.5
14.380000000,38408.5
14.420000000,40326.7
14.460000000,38581.0
14.500000000,32693.3
14.540000000,26099.0
14.580000000,21154.2
14.620000000,18450.0
14.660000000,16839.1
14.700000000,15735.6
14.740000000,14564.0
14.780000000,14070.5
14.820000000,13599.1
14.860000000,13195.8
14.900000000,12815.5
14.940000000,12608.0
14.980000000,12471.0
15.020000000,12300.5
15.060000000,11878.6
15.100000000,11932.2
15.140000000,11858.0
15.180000000,11654.5
15.220000000,11483.9
15.260000000,11553.3
15.300000000,11266.5
15.340000000,11169.4
15.380000000,11262.7
15.420000000,11166.6
15.460000000,10861.8
15.500000000,10930.5
15.540000000,10907.4
15.580000000,10841.8
15.620000000,10683.6
15.660000000,10707.2
15.700000000,10611.0
15.740000000,10743.9
15.780000000,10611.5
15.820000000,10643.5
15.860000000,10555.2
15.900000000,10527.2
15.940000000,10593.5
15.980000000,10724.9
16.020000000,10823.3
16.060000000,10707.0
16.100000000,10351.2
16.140000000,10248.9
16.180000000,10268.6
16.220000000,10150.1
16.260000000,10214.5
16.300000000,10174.3
16.340000000,10154.6
16.380000000,10147.0
16.420000000,9953.2
16.460000000,9886.4
16.500000000,9801.6
16.540000000,9969.7
16.580000000,9906.9
16.620000000,9944.0
16.660000000,9926.9
16.700000000,9776.5
16.740000000,9944.0
16.780000000,9985.5
16.820000000,9832.1
16.860000000,9777.2
16.900000000,9864.5
16.940000000,9918.1
16.980000000,9824.0
17.020000000,9788.1
17.060000000,9690.4
17.100000000,9753.1
17.140000000,9711.4
17.180000000,9497.9
17.220000000,9601.1
17.260000000,9451.5
17.300000000,9547.2
17.340000000,9523.4
17.380000000,9642.2
17.420000000,9498.7
17.460000000,9500.1
17.500000000,9564.8
17.540000000,9516.6
17.580000000,9497.9
17.620000000,9455.5
17.660000000,9546.7
17.700000000,9577.0
17.740000000,9406.2
17.780000000,9583.4
17.820000000,9460.6
17.860000000,9644.8
17.900000000,9517.8
17.940000000,9511.3
17.980000000,9514.2
18.020000000,9326.1
18.060000000,9446.0
18.100000000,9556.6
18.140000000,9582.7
18.180000000,9466.8
18.220000000,9619.1
18.260000000,9530.2
18.300000000,9606.7
18.340000000,9805.8
18.380000000,9869.7
18.420000000,9799.2
18.460000000,9786.6
18.500000000,9892.7
18.540000000,9947.1
18.580000000,10004.2
18.620000000,10008.4
18.660000000,10066.4
18.700000000,10132.1
18.740000000,10283.9
18.780000000,10378.0
18.820000000,10324.4
18.860000000,10197.3
18.900000000,10213.7
18.940000000,10522.2
18.980000000,10514.2
19.020000000,10608.3
19.060000000,10559.7
19.100000000,10553.2
19.140000000,10589.3
19.180000000,10650.9
19.220000000,10816.7
19.260000000,10710.4
19.300000000,10849.1
19.340000000,10845.2
19.380000000,11085.0
19.420000000,11028.5
19.460000000,11225.6
19.500000000,11343.2
19.540000000,11317.7
19.580000000,11411.0
19.620000000,11559.7
19.660000000,11628.5
19.700000000,11602.9
19.740000000,11904.2
19.780000000,11999.1
19.820000000,12197.4
19.860000000,12439.8
19.900000000,12555.2
19.940000000,12749.7
19.980000000,13029.4
20.020000000,13227.3
20.060000000,13653.1
20.100000000,14067.8
20.140000000,14447.3
20.180000000,15060.3
20.220000000,15394.5
20.260000000,16424.3
20.300000000,17514.3
20.340000000,18540.5
20.380000000,20313.4
20.420000000,22379.1
20.460000000,25128.3
20.500000000,28373.5
20.540000000,31977.5
20.580000000,32867.4
20.620000000,31331.9
20.660000000,27949.5
20.700000000,24606.9
20.740000000,21741.3
20.780000000,19589.6
20.820000000,18165.1
20.860000000,17282.9
20.900000000,16425.2
20.940000000,15653.0
20.980000000,15342.0
21.020000000,15027.3
21.060000000,14540.0
21.100000000,14430.7
21.140000000,14357.6
21.180000000,14072.1
21.220000000,14250.4
21.260000000,14374.2
21.300000000,14670.9
21.340000000,14798.8
21.380000000,15142.1
21.420000000,15680.9
21.460000000,16143.8
21.500000000,16664.3
21.540000000,17688.9
21.580000000,18565.4
21.620000000,19361.4
21.660000000,20640.3
21.700000000,21251.9
21.740000000,21723.4
21.780000000,21486.0
21.820000000,19668.4
21.860000000,17789.9
21.900000000,15819.9
21.940000000,14363.6
21.980000000,13362.9
22.020000000,12868.8
22.060000000,12104.6
22.100000000,11763.9
22.140000000,11497.6
22.180000000,11197.7
22.220000000,10722.2
22.260000000,10545.3
22.300000000,10291.6
22.340000000,10022.1
22.380000000,9674.4
22.420000000,9653.3
22.460000000,9496.8
22.500000000,9323.3
22.540000000,9080.7
22.580000000,9056.6
22.620000000,8783.6
22.660000000,8830.9
22.700000000,8643.4
22.740000000,8748.3
22.780000000,8769.8
22.820000000,8705.4
22.860000000,8754.4
22.900000000,8602.4
22.940000000,8469.5
22.980000000,8627.6
23.020000000,8291.8
23.060000000,8260.5
23.100000000,8127.3
23.140000000,8066.8
23.180000000,7900.7
23.220000000,7624.3
23.260000000,7604.2
23.300000000,7707.3
23.340000000,7566.1
23.380000000,7680.9
23.420000000,7467.4
23.460000000,7479.9
23.500000000,7445.0
23.540000000,7651.6
23.580000000,7399.4
23.620000000,7457.4
23.660000000,7388.1
23.700000000,7386.0
23.740000000,7388.6
23.780000000,7341.6
23.820000000,7380.5
23.860000000,7310.4
23.900000000,7341.9
23.940000000,7482.8
23.980000000,7531.8
24.020000000,7629.5
24.060000000,7765.1
24.100000000,8241.5
24.140000000,9413.1
24.180000000,10333.7
24.220000000,10116.7
24.260000000,8913.4
24.300000000,7847.9
24.340000000,7328.1
24.380000000,7215.2
24.420000000,7126.2
24.460000000,6878.3
24.500000000,6963.2
24.540000000,6956.7
24.580000000,6814.2
24.620000000,6966.4
24.660000000,6968.7
24.700000000,6945.1
24.740000000,6785.1
24.780000000,6865.7
24.820000000,6792.9
24.860000000,6784.8
24.900000000,6718.6
24.940000000,6829.3
24.980000000,6798.0
25.020000000,6772.7
25.060000000,6866.8
25.100000000,6809.6
25.140000000,6777.4
25.180000000,6723.9
25.220000000,6785.3
25.260000000,6745.1
25.300000000,6858.2
25.340000000,6955.4
25.380000000,6865.8
25.420000000,7022.0
25.460000000,6847.2
25.500000000,7042.0
25.540000000,7067.2
25.580000000,7112.8
25.620000000,7038.4
25.660000000,6936.5
25.700000000,6773.5
25.740000000,6757.3
25.780000000,6739.0
25.820000000,6694.4
25.860000000,6637.8
25.900000000,6722.2
25.940000000,6609.7
25.980000000,6770.7
26.020000000,6603.5
26.060000000,6589.7
26.100000000,6567.7
26.140000000,6664.8
26.180000000,6574.2
26.220000000,6651.5
26.260000000,6625.0
26.300000000,6524.1
26.340000000,6646.5
26.380000000,6615.6
26.420000000,6596.5
26.460000000,6665.9
26.500000000,6614.9
26.540000000,6597.0
26.580000000,6550.5
26.620000000,6562.2
26.660000000,6601.3
26.700000000,6539.1
26.740000000,6678.1
26.780000000,6669.8
26.820000000,6644.1
26.860000000,6637.7
26.900000000,6523.3
26.940000000,6615.9
26.980000000,6493.7
27.020000000,6419.7
27.060000000,6393.9
27.100000000,6548.3
27.140000000,6434.7
27.180000000,6564.6
27.220000000,6627.6
27.260000000,6673.0
27.300000000,6924.7
27.340000000,7081.6
27.380000000,7134.3
27.420000000,6890.5
27.460000000,6835.6
27.500000000,6647.3
27.540000000,6686.7
27.580000000,6573.3
27.620000000,6529.3
27.660000000,6592.3
27.700000000,6688.7
27.740000000,6724.0
27.780000000,6811.5
27.820000000,6843.4
27.860000000,6877.7
27.900000000,7015.4
27.940000000,7168.4
27.980000000,7371.5
28.020000000,7599.8
28.060000000,7694.4
28.100000000,7724.3
28.140000000,7766.7
28.180000000,7658.0
28.220000000,7690.5
28.260000000,7666.7
28.300000000,7537.9
28.340000000,7362.4
28.380000000,7589.2
28.420000000,7665.6
28.460000000,7754.6
28.500000000,7863.1
28.540000000,8086.1
28.580000000,8247.4
28.620000000,8544.2
28.660000000,8832.8
28.700000000,9288.9
28.740000000,9676.2
28.780000000,10170.3
28.820000000,10662.4
28.860000000,11577.1
28.900000000,12587.7
28.940000000,13607.3
28.980000000,14958.3
29.020000000,16440.2
29.060000000,18182.0
29.100000000,19939.5
29.140000000,21882.0
29.180000000,23133.1
29.220000000,23056.7
29.260000000,22096.7
29.300000000,19750.4
29.340000000,16968.1
29.380000000,14884.7
29.420000000,13152.6
29.460000000,12002.5
29.500000000,11347.6
29.540000000,10666.0
29.580000000,10313.2
29.620000000,10092.2
29.660000000,9656.7
29.700000000,9616.0
29.740000000,9620.4
29.780000000,9532.9
29.820000000,9298.9
29.860000000,9340.5
29.900000000,9308.6
29.940000000,9287.5
29.980000000,9319.5
30.020000000,9481.2
30.060000000,9564.7
30.100000000,9560.3
30.140000000,9634.0
30.180000000,9997.4
30.220000000,10025.3
30.260000000,10267.4
30.300000000,10363.9
30.340000000,10568.0
30.380000000,10803.4
30.420000000,11096.8
30.460000000,11537.0
30.500000000,11811.5
30.540000000,12360.1
30.580000000,12725.5
30.620000000,13297.5
30.660000000,14317.9
30.700000000,15232.1
30.740000000,16440.1
30.780000000,18385.0
30.820000000,20819.9
30.860000000,24500.7
30.900000000,30632.4
30.940000000,40091.6
30.980000000,45277.6
31.020000000,47485.0
31.060000000,50337.6
31.100000000,53594.5
31.140000000,55919.0
31.180000000,55794.0
31.220000000,52125.3
31.260000000,46944.5
31.300000000,41449.9
31.340000000,36986.6
31.380000000,33599.6
31.420000000,30869.0
31.460000000,28317.9
31.500000000,26540.4
31.540000000,25251.0
31.580000000,23843.1
31.620000000,22905.4
31.660000000,22015.1
31.700000000,21285.9
31.740000000,20375.2
31.780000000,19946.5
31.820000000,19404.0
31.860000000,19007.7
31.900000000,18621.6
31.940000000,18066.0
31.980000000,17195.3
32.020000000,16527.6
32.060000000,15807.6
32.100000000,15309.5
32.140000000,14692.6
32.180000000,14166.3
32.220000000,14076.9
32.260000000,13824.1
32.300000000,13443.4
32.340000000,13422.7
32.380000000,13517.1
32.420000000,14021.9
32.460000000,14733.7
32.500000000,14240.4
32.540000000,13192.3
32.580000000,11605.7
32.620000000,10425.8
32.660000000,10135.6
32.700000000,9939.1
32.740000000,9728.9
32.780000000,9657.9
32.820000000,9390.5
32.860000000,8939.4
32.900000000,8805.8
32.940000000,8247.6
32.980000000,8212.8
33.020000000,7976.3
33.060000000,7965.8
33.100000000,7959.2
33.140000000,7714.8
33.180000000,7630.9
33.220000000,7759.6
33.260000000,7561.2
33.300000000,7464.1
33.340000000,7409.9
33.380000000,7219.7
33.420000000,7161.8
33.460000000,7303.6
33.500000000,7132.5
33.540000000,7119.7
33.580000000,6955.9
33.620000000,7027.9
33.660000000,6858.0
33.700000000,6907.0
33.740000000,6766.7
33.780000000,6770.5
33.820000000,6778.2
33.860000000,6679.9
33.900000000,6701.3
33.940000000,6716.5
33.980000000,6614.3
34.020000000,6615.0
34.060000000,6637.1
34.100000000,6561.4
34.140000000,6626.3
34.180000000,6544.3
34.220000000,6608.5
34.260000000,6470.0
34.300000000,6461.9
34.340000000,6448.9
34.380000000,6448.9
34.420000000,6385.8
34.460000000,6503.9
34.500000000,6287.7
34.540000000,6440.0
34.580000000,6519.6
34.620000000,6506.5
34.660000000,6464.6
34.700000000,6454.5
34.740000000,6333.2
34.780000000,6365.2
34.820000000,6378.2
34.860000000,6261.7
34.900000000,6212.0
34.940000000,6334.7
34.980000000,6246.4
35.020000000,6246.3
35.060000000,6370.3
35.100000000,6222.0
35.140000000,6316.2
35.180000000,6277.3
35.220000000,6255.0
35.260000000,6250.8
35.300000000,6210.4
35.340000000,6151.2
35.380000000,6089.5
35.420000000,6268.3
35.460000000,6417.5
35.500000000,6182.7
35.540000000,6215.0
35.580000000,6289.2
35.620000000,6214.6
35.660000000,6115.1
35.700000000,6210.7
35.740000000,6133.7
35.780000000,6018.3
35.820000000,6318.1
35.860000000,6184.2
35.900000000,6260.1
35.940000000,6416.3
35.980000000,6258.1
36.020000000,6312.3
36.060000000,6479.8
36.100000000,6409.0
36.140000000,6465.3
36.180000000,6589.9
36.220000000,6841.2
36.260000000,6885.5
36.300000000,6901.4
36.340000000,7095.3
36.380000000,7156.9
36.420000000,7292.9
36.460000000,7410.7
36.500000000,7416.1
36.540000000,7818.4
36.580000000,7707.1
36.620000000,8082.6
36.660000000,8249.4
36.700000000,8378.4
36.740000000,8160.7
36.780000000,8152.1
36.820000000,8267.0
36.860000000,7861.2
36.900000000,7403.8
36.940000000,7010.8
36.980000000,6908.4
37.020000000,6522.6
37.060000000,6307.5
37.100000000,6197.6
37.140000000,6211.6
37.180000000,6277.7
37.220000000,6222.4
37.260000000,6280.3
37.300000000,6056.1
37.340000000,5897.7
37.380000000,5932.9
37.420000000,5829.9
37.460000000,5768.9
37.500000000,5743.7
37.540000000,5841.8
37.580000000,5640.8
37.620000000,5648.3
37.660000000,5636.7
37.700000000,5616.5
37.740000000,5644.8
37.780000000,5510.4
37.820000000,5401.2
37.860000000,5489.2
37.900000000,5513.9
37.940000000,5508.0
37.980000000,5487.2
38.020000000,5410.5
38.060000000,5472.9
38.100000000,5509.6
38.140000000,5459.7
38.180000000,5463.9
38.220000000,5499.5
38.260000000,5545.3
38.300000000,5564.6
38.340000000,5776.8
38.380000000,5922.7
38.420000000,6036.1
38.460000000,6201.8
38.500000000,6523.7
38.540000000,6859.2
38.580000000,7028.1
38.620000000,7003.4
38.660000000,6876.2
38.700000000,6658.9
38.740000000,6295.0
38.780000000,5981.1
38.820000000,5810.7
38.860000000,5620.1
38.900000000,5525.7
38.940000000,5493.5
38.980000000,5372.3
39.020000000,5345.7
39.060000000,5192.8
39.100000000,5314.3
39.140000000,5071.7
39.180000000,5235.8
39.220000000,5236.9
39.260000000,5028.7
39.300000000,5185.8
39.340000000,5084.4
39.380000000,5147.2
39.420000000,5118.7
39.460000000,5072.0
39.500000000,5011.4
39.540000000,5078.9
39.580000000,5188.7
39.620000000,4985.4
39.660000000,4982.2
39.700000000,5095.3
39.740000000,5071.1
39.780000000,5069.3
39.820000000,5012.6
39.860000000,5148.6
39.900000000,5135.6
39.940000000,5087.7
39.980000000,5022.8
40.020000000,5027.8
40.060000000,5243.2
40.100000000,5047.8
40.140000000,5104.1
40.180000000,5079.2
40.220000000,5157.0
40.260000000,5210.0
40.300000000,5157.5
40.340000000,5125.1
40.380000000,5123.0
40.420000000,5359.5
40.460000000,5244.5
40.500000000,5187.6
40.540000000,5295.0
40.580000000,5201.4
40.620000000,5149.2
40.660000000,5262.7
40.700000000,5273.1
40.740000000,5298.9
40.780000000,5231.7
40.820000000,5376.0
40.860000000,5175.3
40.900000000,5321.7
40.940000000,5426.0
40.980000000,5232.3
41.020000000,5262.7
41.060000000,5132.0
41.100000000,5237.3
41.140000000,5095.4
41.180000000,5194.5
41.220000000,5242.9
41.260000000,5259.0
41.300000000,5121.8
41.340000000,5303.7
41.380000000,5340.1
41.420000000,5526.4
41.460000000,5522.2
41.500000000,5507.0
41.540000000,5862.2
41.580000000,5834.6
41.620000000,6004.9
41.660000000,6073.1
41.700000000,6187.8
41.740000000,6394.3
41.780000000,6756.8
41.820000000,7059.6
41.860000000,7441.5
41.900000000,7787.0
41.940000000,7949.8
41.980000000,7961.7
42.020000000,7772.9
42.060000000,7402.1
42.100000000,6916.0
42.140000000,6360.0
42.180000000,6171.1
42.220000000,5834.2
42.260000000,5639.5
42.300000000,5247.8
42.340000000,5114.1
42.380000000,5151.2
42.420000000,4955.7
42.460000000,4897.8
42.500000000,4886.2
42.540000000,4937.7
42.580000000,5188.5
42.620000000,5555.9
42.660000000,5320.1
42.700000000,5136.2
42.740000000,5028.8
42.780000000,4755.0
42.820000000,4778.9
42.860000000,4555.6
42.900000000,4637.3
42.940000000,4614.0
42.980000000,4513.0
43.020000000,4451.9
43.060000000,4533.9
43.100000000,4619.2
43.140000000,4597.1
43.180000000,4600.2
43.220000000,4477.4
43.260000000,4544.5
43.300000000,4497.9
43.340000000,4462.3
43.380000000,4559.9
43.420000000,4454.0
43.460000000,4390.4
43.500000000,4481.4
43.540000000,4588.0
43.580000000,4453.8
43.620000000,4516.3
43.660000000,4400.9
43.700000000,4508.4
43.740000000,4580.0
43.780000000,4460.7
43.820000000,4505.1
43.860000000,4473.2
43.900000000,4525.2
43.940000000,4509.5
43.980000000,4500.5
44.020000000,4486.6
44.060000000,4427.0
44.100000000,4503.5
44.140000000,4420.6
44.180000000,4435.4
44.220000000,4438.6
44.260000000,4465.9
44.300000000,4385.0
44.340000000,4425.4
44.380000000,4370.9
44.420000000,4366.6
44.460000000,4279.4
44.500000000,4337.0
44.540000000,4273.8
44.580000000,4287.4
44.620000000,4304.4
44.660000000,4312.0
44.700000000,4265.2
44.740000000,4249.0
44.780000000,4273.5
44.820000000,4304.2
44.860000000,4315.8
44.900000000,4238.2
44.940000000,4166.7
44.980000000,4294.6